Workbook

Sheet Niveau initial
A1: Les formules de bases
C3: Somme | E3: Années
C4: € | E4: 0 | F4: =E4+1 -> 1 | G4: =F4+1 -> 2 | H4: =G4+1 -> 3 | I4: =H4+1 -> 4
A6: Investissement initial (Capex) | C6: =SUM(E6:I6) -> -10000 | E6: -10000
A7: Flux annuels (Recettes - Dépenses) | C7: =SUM(E7:I7) -> 16000 | F7: 4000 | G7: 4000 | H7: 4000 | I7: 4000
A9: Total | C9: =SUM(E9:I9) -> 6000 | E9: =SUM(E6:E7) -> -10000 | F9: =SUM(F6:F7) -> 4000 | G9: =SUM(G6:G7) -> 4000 | H9: =SUM(H6:H7) -> 4000 | I9: =SUM(I6:I7) -> 4000
A10: Total cumulatif | E10: =E9 -> -10000 | F10: =E10+F9 -> -6000 | G10: =F10+G9 -> -2000 | H10: =G10+H9 -> 2000 | I10: =H10+I9 -> 6000
A12: Temps de retour | C12: ans
A14: Taux d'actualisation | B14: 0.1
A16: Valeur actuelle nette
A17: - somme | C17: =SUM(E17:I17) -> 2679.4618 | E17: =E9/(1+$B$14)^E4 -> -10000 | F17: =F9/(1+$B$14)^F4 -> 3636.3636 | G17: =G9/(1+$B$14)^G4 -> 3305.7851 | H17: =H9/(1+$B$14)^H4 -> 3005.2592 | I17: =I9/(1+$B$14)^I4 -> 2732.0538
A18: - avec formule | C18: =E9+NPV(B14,F9:I9) -> 2679.4618
A20: TRI | C20: =IRR(E9:I9) -> 0.2186227
A24: Exemple de calcul d'un TRI simple :
C26: Années
C27: 0 | D27: =C27+1 -> 1 | E27: =D27+1 -> 2
B28: Capex | C28: 100
B29: Flux | D29: 65 | E29: 75
B30: Total | C30: =C29-C28 -> -100 | D30: =D29-D28 -> 65 | E30: =E29-E28 -> 75
B32: TRI : | C32: =IRR(C30:E30) -> 0.25
B34: VAN @ 25% : | D34: =D30/(1+$C$32) -> 52 | E34: =E30/(1+$C$32)^2 -> 48

Sheet Niveau intermédiare
A1: LCOE Solaire
A3: Dépenses
B4: Puissance | C4: Coût | F4: Somme | G4: VAN | I4: Années
B5: Wc | C5: €/Wc | D5: € | F5: € | G5: € | I5: 0 | J5: =I5+1 -> 1 | K5: =J5+1 -> 2 | L5: =K5+1 -> 3 | M5: =L5+1 -> 4 | N5: =M5+1 -> 5 | O5: =N5+1 -> 6 | P5: =O5+1 -> 7 | Q5: =P5+1 -> 8 | ... X5: =W5+1 -> 15
A6: Investissement | B6: 15000 | C6: 3 | D6: =B6*C6 -> 45000 | F6: =SUM(I6:X6) -> 45000 | G6: =I6+NPV($B$47,J6:X6) -> 45000 | I6: =D6 -> 45000
A7: Maintenance | B7: =B6 -> 15000 | C7: 0.02 | D7: =B7*C7 -> 300 | F7: =SUM(I7:X7) -> 4500 | G7: =I7+NPV($B$47,J7:X7) -> 2281.8239 | J7: =D7 -> 300 | K7: =J7 -> 300 | L7: =K7 -> 300 | M7: =L7 -> 300 | N7: =M7 -> 300 | O7: =N7 -> 300 | P7: =O7 -> 300 | Q7: =P7 -> 300 | R7: =Q7 -> 300 | ... X7: =W7 -> 300
A8: Total | F8: =SUM(F6:F7) -> 49500 | G8: =SUM(G6:G7) -> 47281.824
A10: Production
A12: Irradiation | B12: 5500 | C12: Wh/m²/jour
A13: Rendement | B13: 0.65
A14: Production par jour | B14: =B6*B12/1000*B13 -> 53625 | C14: Wh/jour
A15: Production par an | B15: =B14*365/1000 -> 19573.125 | C15: kWh/an | F15: =SUM(I15:X15) -> 313170 | G15: =I15+NPV($B$47,J15:X15) -> 168447.87 | I15: =$B$15 -> 19573.125 | J15: =$B$15 -> 19573.125 | K15: =$B$15 -> 19573.125 | L15: =$B$15 -> 19573.125 | M15: =$B$15 -> 19573.125 | N15: =$B$15 -> 19573.125 | O15: =$B$15 -> 19573.125 | P15: =$B$15 -> 19573.125 | ... X15: =$B$15 -> 19573.125
A17: Production PV = (Puissance PV x Irradiation) / (Rendement x 1000)
A19: LCOE
A21: LCOE simplifiée | B21: =F8/F15 -> 0.15806112 | C21: €/kWh
A23: Discount rate | B23: 0.1
A24: LCOE actualisée | B24: =G8/G15 -> 0.28069114 | C24: €/kWh
A26: LCOE = somme des dépenses / somme de la production * sur la durée de vie
A28: LCOE Groupe électrogène
A30: Dépenses
B31: Puissance | C31: Coût | F31: Somme | G31: VAN | I31: Années
B32: VA | C32: €/VA | D32: € | F32: € | G32: € | I32: 0 | J32: =I32+1 -> 1 | K32: =J32+1 -> 2 | L32: =K32+1 -> 3 | M32: =L32+1 -> 4 | N32: =M32+1 -> 5 | O32: =N32+1 -> 6 | P32: =O32+1 -> 7 | Q32: =P32+1 -> 8 | ... X32: =W32+1 -> 15
A33: Investissement | B33: 8000 | C33: 0.5 | D33: =B33*C33 -> 4000 | F33: =SUM(I33:X33) -> 16000 | G33: =I33+NPV($B$47,J33:X33) -> 13947.408 | I33: =D33 -> 4000 | N33: 4000 | S33: 4000 | X33: 4000
A34: Maintenance | B34: =B33 -> 8000 | C34: 0.09 | D34: =B34*C34 -> 720 | F34: =SUM(I34:X34) -> 10800 | G34: =I34+NPV($B$47,J34:X34) -> 5476.3772 | J34: =D34 -> 720 | K34: =J34 -> 720 | L34: =K34 -> 720 | M34: =L34 -> 720 | N34: =M34 -> 720 | O34: =N34 -> 720 | P34: =O34 -> 720 | Q34: =P34 -> 720 | R34: =Q34 -> 720 | ... X34: =W34 -> 720
B36: Conso | C36: Coût | F36: Somme | G36: VAN
B37: L/kWh | C37: €/L | D37: €/Wh | F37: € | G37: €
A38: Carburant | B38: 0.4 | C38: 1 | D38: =B38*C38 -> 0.4 | F38: =SUM(I38:X38) -> 125268 | G38: =I38+NPV($B$47,J38:X38) -> 67379.148 | I38: =$D$38*I15 -> 7829.25 | J38: =$D$38*J15 -> 7829.25 | K38: =$D$38*K15 -> 7829.25 | L38: =$D$38*L15 -> 7829.25 | M38: =$D$38*M15 -> 7829.25 | N38: =$D$38*N15 -> 7829.25 | O38: =$D$38*O15 -> 7829.25 | P38: =$D$38*P15 -> 7829.25 | ... X38: =$D$38*X15 -> 7829.25
A41: Total | F41: =SUM(F33:F34)+F38 -> 152068 | G41: =SUM(G33:G34)+G38 -> 86802.933
A43: LCOE
A45: LCOE simplifiée | B45: =F41/F15 -> 0.48557652 | C45: €/kWh
A47: Discount rate | B47: =B23 -> 0.1
A48: LCOE actualisée | B48: =G41/G15 -> 0.51531036 | C48: €/kWh
A50: LCOE = somme des dépenses / somme de la production * sur la durée de vie
A52: Temps de retour sur investissement
A55: Dépenses solaires | B55: =I4 -> Années
B56: 0 | C56: =B56+1 -> 1 | D56: =C56+1 -> 2 | E56: =D56+1 -> 3 | F56: =E56+1 -> 4 | G56: =F56+1 -> 5 | H56: =G56+1 -> 6 | I56: =H56+1 -> 7 | J56: =I56+1 -> 8 | ... Q56: =P56+1 -> 15
A57: Investissement | B57: =I6 -> 45000 | C57: =J6 -> 0 | D57: =K6 -> 0 | E57: =L6 -> 0 | F57: =M6 -> 0 | G57: =N6 -> 0 | H57: =O6 -> 0 | I57: =P6 -> 0 | ... Q57: =X6 -> 0
A58: Maintenance | B58: =I7 -> 0 | C58: =J7 -> 300 | D58: =K7 -> 300 | E58: =L7 -> 300 | F58: =M7 -> 300 | G58: =N7 -> 300 | H58: =O7 -> 300 | I58: =P7 -> 300 | ... Q58: =X7 -> 300
A60: Total "Solaire" | B60: =SUM(B57:B59) -> 45000 | C60: =SUM(C57:C59) -> 300 | D60: =SUM(D57:D59) -> 300 | E60: =SUM(E57:E59) -> 300 | F60: =SUM(F57:F59) -> 300 | G60: =SUM(G57:G59) -> 300 | H60: =SUM(H57:H59) -> 300 | I60: =SUM(I57:I59) -> 300 | ... Q60: =SUM(Q57:Q59) -> 300
A61: Total cumulé "Solaire" | B61: =B60 -> 45000 | C61: =B61+C60 -> 45300 | D61: =C61+D60 -> 45600 | E61: =D61+E60 -> 45900 | F61: =E61+F60 -> 46200 | G61: =F61+G60 -> 46500 | H61: =G61+H60 -> 46800 | I61: =H61+I60 -> 47100 | J61: =I61+J60 -> 47400 | ... Q61: =P61+Q60 -> 49500
...

Sheet Niveau avancé
A1: Hypothèses économique
A3: Nombre d'années | B3: ans | C3: 15 | D3: non modifiable
A4: Taux d'actualisation | B4: % | C4: 0.1
A6: Solaire Qualité
B9: Unité | C9: Coût unitaire | D9: Quantité | E9: Coût total | G9: Remplacement | I9: VAN | J9: Années
B10: ¤ | C10: €/ ¤ | D10: # | E10: € | F10: % total | G10: ans | I10: # | J10: 0 | K10: =J10+1 -> 1 | L10: =K10+1 -> 2 | M10: =L10+1 -> 3 | N10: =M10+1 -> 4 | O10: =N10+1 -> 5 | P10: =O10+1 -> 6 | Q10: =P10+1 -> 7 | R10: =Q10+1 -> 8 | ... Y10: =X10+1 -> 15
A11: Investissement initial (Capex)
A13: Electronique de puissance | B13: kW | C13: 525 | D13: 5 | E13: =C13*D13 -> 2625 | F13: =E13/E$19 -> 0.16005122 | G13: 16 | I13: =NPV($C$4,K13:Y13)+J13 -> 2625 | J13: =E13 -> 2625 | K13: =IF(ROUND(K$10/$G13,0)=K$10/$G13,1,0)*$J13 -> 0 | L13: =IF(ROUND(L$10/$G13,0)=L$10/$G13,1,0)*$J13 -> 0 | M13: =IF(ROUND(M$10/$G13,0)=M$10/$G13,1,0)*$J13 -> 0 | N13: =IF(ROUND(N$10/$G13,0)=N$10/$G13,1,0)*$J13 -> 0 | O13: =IF(ROUND(O$10/$G13,0)=O$10/$G13,1,0)*$J13 -> 0 | P13: =IF(ROUND(P$10/$G13,0)=P$10/$G13,1,0)*$J13 -> 0 | Q13: =IF(ROUND(Q$10/$G13,0)=Q$10/$G13,1,0)*$J13 -> 0 | R13: =IF(ROUND(R$10/$G13,0)=R$10/$G13,1,0)*$J13 -> 0 | ... Y13: =IF(ROUND(Y$10/$G13,0)=Y$10/$G13,1,0)*$J13 -> 0
A14: Batteries | B14: kWh | C14: 425 | D14: 10 | E14: =C14*D14 -> 4250 | F14: =E14/E$19 -> 0.25913054 | G14: 16 | I14: =NPV($C$4,K14:Y14)+J14 -> 4250 | J14: =E14 -> 4250 | K14: =IF(ROUND(K$10/$G14,0)=K$10/$G14,1,0)*$J14 -> 0 | L14: =IF(ROUND(L$10/$G14,0)=L$10/$G14,1,0)*$J14 -> 0 | M14: =IF(ROUND(M$10/$G14,0)=M$10/$G14,1,0)*$J14 -> 0 | N14: =IF(ROUND(N$10/$G14,0)=N$10/$G14,1,0)*$J14 -> 0 | O14: =IF(ROUND(O$10/$G14,0)=O$10/$G14,1,0)*$J14 -> 0 | P14: =IF(ROUND(P$10/$G14,0)=P$10/$G14,1,0)*$J14 -> 0 | Q14: =IF(ROUND(Q$10/$G14,0)=Q$10/$G14,1,0)*$J14 -> 0 | R14: =IF(ROUND(R$10/$G14,0)=R$10/$G14,1,0)*$J14 -> 0 | ... Y14: =IF(ROUND(Y$10/$G14,0)=Y$10/$G14,1,0)*$J14 -> 0
A15: Panneaux | B15: Wc | C15: 0.4 | D15: 5500 | E15: =C15*D15 -> 2200 | F15: =E15/E$19 -> 0.13413816 | G15: 25 | I15: =NPV($C$4,K15:Y15)+J15 -> 2200 | J15: =E15 -> 2200 | K15: =IF(ROUND(K$10/$G15,0)=K$10/$G15,1,0)*$J15 -> 0 | L15: =IF(ROUND(L$10/$G15,0)=L$10/$G15,1,0)*$J15 -> 0 | M15: =IF(ROUND(M$10/$G15,0)=M$10/$G15,1,0)*$J15 -> 0 | N15: =IF(ROUND(N$10/$G15,0)=N$10/$G15,1,0)*$J15 -> 0 | O15: =IF(ROUND(O$10/$G15,0)=O$10/$G15,1,0)*$J15 -> 0 | P15: =IF(ROUND(P$10/$G15,0)=P$10/$G15,1,0)*$J15 -> 0 | Q15: =IF(ROUND(Q$10/$G15,0)=Q$10/$G15,1,0)*$J15 -> 0 | R15: =IF(ROUND(R$10/$G15,0)=R$10/$G15,1,0)*$J15 -> 0 | ... Y15: =IF(ROUND(Y$10/$G15,0)=Y$10/$G15,1,0)*$J15 -> 0
A16: Câbles et accessoires | B16: Wc | C16: 0.2 | D16: =$D$15 -> 5500 | E16: =C16*D16 -> 1100 | F16: =E16/E$19 -> 0.067069081 | G16: 25 | I16: =NPV($C$4,K16:Y16)+J16 -> 1100 | J16: =E16 -> 1100 | K16: =IF(ROUND(K$10/$G16,0)=K$10/$G16,1,0)*$J16 -> 0 | L16: =IF(ROUND(L$10/$G16,0)=L$10/$G16,1,0)*$J16 -> 0 | M16: =IF(ROUND(M$10/$G16,0)=M$10/$G16,1,0)*$J16 -> 0 | N16: =IF(ROUND(N$10/$G16,0)=N$10/$G16,1,0)*$J16 -> 0 | O16: =IF(ROUND(O$10/$G16,0)=O$10/$G16,1,0)*$J16 -> 0 | P16: =IF(ROUND(P$10/$G16,0)=P$10/$G16,1,0)*$J16 -> 0 | Q16: =IF(ROUND(Q$10/$G16,0)=Q$10/$G16,1,0)*$J16 -> 0 | R16: =IF(ROUND(R$10/$G16,0)=R$10/$G16,1,0)*$J16 -> 0 | ... Y16: =IF(ROUND(Y$10/$G16,0)=Y$10/$G16,1,0)*$J16 -> 0
A17: Installation | B17: Wc | C17: 0.25 | D17: =$D$15 -> 5500 | E17: =C17*D17 -> 1375 | F17: =E17/E$19 -> 0.083836351 | I17: =NPV($C$4,K17:Y17)+J17 -> 1375 | J17: =E17 -> 1375 | K17: =SUM(K13:K16)*$F17 -> 0 | L17: =SUM(L13:L16)*$F17 -> 0 | M17: =SUM(M13:M16)*$F17 -> 0 | N17: =SUM(N13:N16)*$F17 -> 0 | O17: =SUM(O13:O16)*$F17 -> 0 | P17: =SUM(P13:P16)*$F17 -> 0 | Q17: =SUM(Q13:Q16)*$F17 -> 0 | R17: =SUM(R13:R16)*$F17 -> 0 | ... Y17: =SUM(Y13:Y16)*$F17 -> 0
A18: Markup | B18: Wc | C18: =E18/D18 -> 0.882 | D18: =$D$15 -> 5500 | E18: =SUM(E$13:E17)*F18 -> 4851 | F18: 0.42 | I18: =NPV($C$4,K18:Y18)+J18 -> 4851 | J18: =E18 -> 4851 | K18: =SUM(K13:K17)*$F18 -> 0 | L18: =SUM(L13:L17)*$F18 -> 0 | M18: =SUM(M13:M17)*$F18 -> 0 | N18: =SUM(N13:N17)*$F18 -> 0 | O18: =SUM(O13:O17)*$F18 -> 0 | P18: =SUM(P13:P17)*$F18 -> 0 | Q18: =SUM(Q13:Q17)*$F18 -> 0 | R18: =SUM(R13:R17)*$F18 -> 0 | ... Y18: =SUM(Y13:Y17)*$F18 -> 0
A19: Total | B19: Wc | C19: =E19/D19 -> 2.982 | D19: =$D$15 -> 5500 | E19: =SUM(E13:E18) -> 16401 | F19: =E19/SUM(E$13:E18) -> 1 | I19: =NPV($C$4,K19:Y19)+J19 -> 16401 | J19: =SUM(J13:J18) -> 16401 | K19: =SUM(K13:K18)*$F19 -> 0 | L19: =SUM(L13:L18)*$F19 -> 0 | M19: =SUM(M13:M18)*$F19 -> 0 | N19: =SUM(N13:N18)*$F19 -> 0 | O19: =SUM(O13:O18)*$F19 -> 0 | P19: =SUM(P13:P18)*$F19 -> 0 | Q19: =SUM(Q13:Q18)*$F19 -> 0 | R19: =SUM(R13:R18)*$F19 -> 0 | ... Y19: =SUM(Y13:Y18)*$F19 -> 0
A21: Marge | C21: =E18/E19 -> 0.29577465
A23: Maintenance (Opex) | B23: Wc | C23: 0.02 | D23: =D15 -> 5500 | E23: =C23*D23 -> 110 | F23: =E23/E19 -> 0.0067069081 | G23: 1 | I23: =NPV($C$4,K23:Y23)+K23 -> 946.66875 | K23: =E23 -> 110 | L23: =$K$23 -> 110 | M23: =$K$23 -> 110 | N23: =$K$23 -> 110 | O23: =$K$23 -> 110 | P23: =$K$23 -> 110 | Q23: =$K$23 -> 110 | R23: =$K$23 -> 110 | S23: =$K$23 -> 110 | ... Y23: =$K$23 -> 110
A25: Capex + Opex | B25: Wc | C25: =E25/D25 -> 3.1341216 | D25: =$D$15 -> 5500 | E25: =I25 -> 17237.669 | F25: =E25/E19 -> 1.0510133 | I25: =NPV($C$4,K25:Y25)+J25 -> 17237.669 | J25: =J23+J19 -> 16401 | K25: =K23+K19 -> 110 | L25: =L23+L19 -> 110 | M25: =M23+M19 -> 110 | N25: =N23+N19 -> 110 | O25: =O23+O19 -> 110 | P25: =P23+P19 -> 110 | Q25: =Q23+Q19 -> 110 | ... Y25: =Y23+Y19 -> 110
A27: Production
A29: Irradiation | B29: kWh/m²/j | C29: 5.5
A31: Rendement initial
A32: Panneaux | B32: % | C32: 0.9
A33: Régulateur | B33: % | C33: 0.95
A34: Câbles | B34: % | C34: 0.95
A35: Batteries | B35: % | C35: 0.95
A36: Convertisseur | B36: % | C36: 0.92
A37: Total | C37: =C32*C33*C34*C35*C36 -> 0.7099065
A39: Perte de rendement total | B39: Pts | C39: 8
A40: Perte de rendement par an | B40: Pts | C40: =C39/$C$3 -> 0.53333333 | I40: VAN | J40: Années
A41: Rendement dernière année | B41: % | C41: =(C37*100-C39)/100 -> 0.6299065 | I41: # | J41: 0 | K41: =J41+1 -> 1 | L41: =K41+1 -> 2 | M41: =L41+1 -> 3 | N41: =M41+1 -> 4 | O41: =N41+1 -> 5 | P41: =O41+1 -> 6 | Q41: =P41+1 -> 7 | R41: =Q41+1 -> 8 | ... Y41: =X41+1 -> 15
A43: Rendement du système | B43: % | K43: ='Niveau avancé'!C37 -> 0.7099065 | L43: =(K43*100-'Niveau avancé'!$C$40)/100 -> 0.70457317 | M43: =(L43*100-'Niveau avancé'!$C$40)/100 -> 0.69923983 | N43: =(M43*100-'Niveau avancé'!$C$40)/100 -> 0.6939065 | O43: =(N43*100-'Niveau avancé'!$C$40)/100 -> 0.68857317 | P43: =(O43*100-'Niveau avancé'!$C$40)/100 -> 0.68323983 | Q43: =(P43*100-'Niveau avancé'!$C$40)/100 -> 0.6779065 | R43: =(Q43*100-'Niveau avancé'!$C$40)/100 -> 0.67257317 | S43: =(R43*100-'Niveau avancé'!$C$40)/100 -> 0.66723983 | ... Y43: =(X43*100-'Niveau avancé'!$C$40)/100 -> 0.63523983
A44: Production annuelle | B44: kWh | I44: =NPV($C$4,K44:Y44)+J44 -> 57253.975 | K44: =$D$15*K43*'Niveau avancé'!$C$29*365/1000 -> 7838.2551 | L44: =$D$15*L43*'Niveau avancé'!$C$29*365/1000 -> 7779.3685 | M44: =$D$15*M43*'Niveau avancé'!$C$29*365/1000 -> 7720.4818 | N44: =$D$15*N43*'Niveau avancé'!$C$29*365/1000 -> 7661.5951 | O44: =$D$15*O43*'Niveau avancé'!$C$29*365/1000 -> 7602.7085 | P44: =$D$15*P43*'Niveau avancé'!$C$29*365/1000 -> 7543.8218 | Q44: =$D$15*Q43*'Niveau avancé'!$C$29*365/1000 -> 7484.9351 | R44: =$D$15*R43*'Niveau avancé'!$C$29*365/1000 -> 7426.0485 | ... Y44: =$D$15*Y43*'Niveau avancé'!$C$29*365/1000 -> 7013.8418
A46: LCOE | B46: €/kWh | C46: =(I19+I23)/I44 -> 0.30299501
A48: Solaire Low Cost
B51: Unité | C51: Coût unitaire | D51: Quantité | E51: Coût total | G51: Remplacement | I51: VAN | J51: Années
B52: ¤ | C52: €/ ¤ | D52: # | E52: € | F52: % tot sup | G52: ans | I52: # | J52: 0 | K52: =J52+1 -> 1 | L52: =K52+1 -> 2 | M52: =L52+1 -> 3 | N52: =M52+1 -> 4 | O52: =N52+1 -> 5 | P52: =O52+1 -> 6 | Q52: =P52+1 -> 7 | R52: =Q52+1 -> 8 | ... Y52: =X52+1 -> 15
A53: Investissement initial (Capex)
A55: Electronique de puissance | B55: kW | C55: 250 | D55: 5 | E55: =C55*D55 -> 1250 | F55: =E55/E$61 -> 0.11936023 | G55: 5 | I55: =NPV($C$4,K55:X55)+J55 -> 2508.0808 | J55: =E55 -> 1250 | K55: =IF(ROUND(K$52/$G55,0)=K$52/$G55,1,0)*$J55 -> 0 | L55: =IF(ROUND(L$52/$G55,0)=L$52/$G55,1,0)*$J55 -> 0 | M55: =IF(ROUND(M$52/$G55,0)=M$52/$G55,1,0)*$J55 -> 0 | N55: =IF(ROUND(N$52/$G55,0)=N$52/$G55,1,0)*$J55 -> 0 | O55: =IF(ROUND(O$52/$G55,0)=O$52/$G55,1,0)*$J55 -> 1250 | P55: =IF(ROUND(P$52/$G55,0)=P$52/$G55,1,0)*$J55 -> 0 | Q55: =IF(ROUND(Q$52/$G55,0)=Q$52/$G55,1,0)*$J55 -> 0 | R55: =IF(ROUND(R$52/$G55,0)=R$52/$G55,1,0)*$J55 -> 0 | ... Y55: =IF(ROUND(Y$52/$G55,0)=Y$52/$G55,1,0)*$J55 -> 1250
A56: Batteries | B56: kWh | C56: 125 | D56: 16 | E56: =C56*D56 -> 2000 | F56: =E56/E$61 -> 0.19097637 | G56: 4 | I56: =NPV($C$4,K56:X56)+J56 -> 4936.3033 | J56: =E56 -> 2000 | K56: =IF(ROUND(K$52/$G56,0)=K$52/$G56,1,0)*$J56 -> 0 | L56: =IF(ROUND(L$52/$G56,0)=L$52/$G56,1,0)*$J56 -> 0 | M56: =IF(ROUND(M$52/$G56,0)=M$52/$G56,1,0)*$J56 -> 0 | N56: =IF(ROUND(N$52/$G56,0)=N$52/$G56,1,0)*$J56 -> 2000 | O56: =IF(ROUND(O$52/$G56,0)=O$52/$G56,1,0)*$J56 -> 0 | P56: =IF(ROUND(P$52/$G56,0)=P$52/$G56,1,0)*$J56 -> 0 | Q56: =IF(ROUND(Q$52/$G56,0)=Q$52/$G56,1,0)*$J56 -> 0 | R56: =IF(ROUND(R$52/$G56,0)=R$52/$G56,1,0)*$J56 -> 2000 | ... Y56: =IF(ROUND(Y$52/$G56,0)=Y$52/$G56,1,0)*$J56 -> 0
A57: Panneaux | B57: Wc | C57: 0.3 | D57: 5500 | E57: =C57*D57 -> 1650 | F57: =E57/E$61 -> 0.1575555 | G57: 25 | I57: =NPV($C$4,K57:X57)+J57 -> 1650 | J57: =E57 -> 1650 | K57: =IF(ROUND(K$52/$G57,0)=K$52/$G57,1,0)*$J57 -> 0 | L57: =IF(ROUND(L$52/$G57,0)=L$52/$G57,1,0)*$J57 -> 0 | M57: =IF(ROUND(M$52/$G57,0)=M$52/$G57,1,0)*$J57 -> 0 | N57: =IF(ROUND(N$52/$G57,0)=N$52/$G57,1,0)*$J57 -> 0 | O57: =IF(ROUND(O$52/$G57,0)=O$52/$G57,1,0)*$J57 -> 0 | P57: =IF(ROUND(P$52/$G57,0)=P$52/$G57,1,0)*$J57 -> 0 | Q57: =IF(ROUND(Q$52/$G57,0)=Q$52/$G57,1,0)*$J57 -> 0 | R57: =IF(ROUND(R$52/$G57,0)=R$52/$G57,1,0)*$J57 -> 0 | ... Y57: =IF(ROUND(Y$52/$G57,0)=Y$52/$G57,1,0)*$J57 -> 0
A58: Câbles et accessoires | B58: Wc | C58: 0.2 | D58: =$D$15 -> 5500 | E58: =C58*D58 -> 1100 | F58: =E58/E$61 -> 0.105037 | G58: 25 | I58: =NPV($C$4,K58:X58)+J58 -> 1100 | J58: =E58 -> 1100 | K58: =IF(ROUND(K$52/$G58,0)=K$52/$G58,1,0)*$J58 -> 0 | L58: =IF(ROUND(L$52/$G58,0)=L$52/$G58,1,0)*$J58 -> 0 | M58: =IF(ROUND(M$52/$G58,0)=M$52/$G58,1,0)*$J58 -> 0 | N58: =IF(ROUND(N$52/$G58,0)=N$52/$G58,1,0)*$J58 -> 0 | O58: =IF(ROUND(O$52/$G58,0)=O$52/$G58,1,0)*$J58 -> 0 | P58: =IF(ROUND(P$52/$G58,0)=P$52/$G58,1,0)*$J58 -> 0 | Q58: =IF(ROUND(Q$52/$G58,0)=Q$52/$G58,1,0)*$J58 -> 0 | R58: =IF(ROUND(R$52/$G58,0)=R$52/$G58,1,0)*$J58 -> 0 | ... Y58: =IF(ROUND(Y$52/$G58,0)=Y$52/$G58,1,0)*$J58 -> 0
...
